<?xml version="1.0"?>

<robot name="rosguard" xmlns:xacro="http://ros.org/wiki/xacro">

  <!--   <xacro:macro name="qbo">   -->
  <xacro:include filename="$(find rosguard_description)/urdf/common_properties.xacro" />
  <xacro:include filename="$(find rosguard_description)/gazebo/rosguard.gazebo.xacro" />

  <!-- Defining the fixed base link of the robot -->
  <link name="base_footprint"/>

    <joint name="base_joint" type="fixed">
      <origin xyz="0 0 0.0102" rpy="0 0 0" />
      <parent link="base_footprint"/>
      <child link="base_link" />
    </joint>

    <link name="base_link">
      <visual>
        <geometry>
          <!-- new mesh -->
          <mesh filename="package://rosguard_description/meshes/base_plate.dae" />
         <material name="white"/>
        </geometry>

      	<origin xyz="0.001 0 -0.034" rpy="0 0 ${M_PI/2}"/>
      </visual>

      <collision>
        <geometry>
          <cylinder length="0.10938" radius="0.178"/>
        </geometry>
        <origin xyz="0.0 0 0.05949" rpy="0 0 0"/>
      </collision>

      <inertial>
        <!-- COM experimentally determined -->
        <origin xyz="0.01 0 0"/>
        <mass value="2.4"/> <!-- 2.4/2.6 kg for small/big battery pack -->

        <inertia ixx="0.019995" ixy="0.0" ixz="0.0"
                 iyy="0.019995" iyz="0.0" 
                 izz="0.03675" />
      </inertial>
    </link>
    
    <joint name="wheel_left_joint" type="continuous">
      <parent link="base_link"/>
      <child link="rosguard_wheel_left_link"/>
      <origin xyz="0 ${0.28/2} 0.026" rpy="${-M_PI/2} 0 0"/>
      <axis xyz="0 0 1"/>
    </joint>

    <link name="rosguard_wheel_left_link">
      <visual>
        <geometry>
          <mesh filename="package://rosguard_description/meshes/wheel.dae"/>
       <material name="black"/>
        </geometry>
        <origin xyz="0 0 0" rpy="0 0 0"/>
      </visual>
      <collision>
        <geometry>
          <cylinder length="0.0206" radius="0.0352"/>
        </geometry>
        <origin rpy="0 0 0" xyz="0 0 0"/>
      </collision>
      <inertial>
        <mass value="0.01" />
        <origin xyz="0 0 0" />
        <inertia ixx="0.001" ixy="0.0" ixz="0.0"
                 iyy="0.001" iyz="0.0" 
                 izz="0.001" />
      </inertial>
    </link>
    
    <joint name="wheel_right_joint" type="continuous">
      <parent link="base_link"/>
      <child link="rosguard_wheel_right_link"/>
      <origin xyz="0.00 -${0.28/2} 0.026" rpy="${-M_PI/2} 0 0"/>
      <axis xyz="0 0 1"/>
    </joint>

    <link name="rosguard_wheel_right_link">
      <visual>
        <geometry>
          <mesh filename="package://rosguard_description/meshes/wheel.dae"/>
       	<material name="white"/>
        </geometry>
        <origin xyz="0 0 0" rpy="0 0 0"/>
      </visual>
      <collision>
        <geometry>
          <cylinder length="0.0206" radius="0.0350"/>
        </geometry>
        <origin rpy="0 0 0" xyz="0 0 0"/>
      </collision>
      <inertial>
        <mass value="0.01" />
        <origin xyz="0 0 0" />
        <inertia ixx="0.001" ixy="0.0" ixz="0.0"
                 iyy="0.001" iyz="0.0" 
                 izz="0.001" />
      </inertial>
    </link>

    <joint name="rosguard_caster_back_joint" type="fixed">
      <parent link="base_link"/>
      <child link="rosguard_caster_back_link"/>
      <origin xyz="-0.135 0.0 0.009" rpy="${-M_PI/2} 0 0"/>
    </joint>

    <link name="rosguard_caster_back_link">
      <collision>
        <geometry>
          <cylinder length="0.0176" radius="0.017"/>
        </geometry>
        <origin rpy="0 0 0" xyz="0 0 0"/>
      </collision>      
      <inertial>
        <mass value="0.01" />
        <origin xyz="0 0 0" />
        <inertia ixx="0.001" ixy="0.0" ixz="0.0"
                 iyy="0.001" iyz="0.0" 
                 izz="0.001" />
      </inertial>
    </link>
    
    <!-- rosguard's sensors -->
</robot>
